<?xml version="1.0" encoding="UTF-8"?><testrun duration="253907" footerText="Generated by PyCharm Community Edition on 2015.09.10. 21:38" name="Unittests in regression_tests">
    <count name="total" value="50"/>
    <count name="failed" value="2"/>
    <count name="passed" value="48"/>
    <suite duration="253907" status="failed" name="regression_tests.UnitTest">
        <test duration="0" status="passed" name="test_problem001"/>
        <test duration="0" status="passed" name="test_problem002"/>
        <test duration="1" status="passed" name="test_problem003"/>
        <test duration="307" status="passed" name="test_problem004"/>
        <test duration="0" status="passed" name="test_problem005"/>
        <test duration="0" status="passed" name="test_problem006"/>
        <test duration="292" status="passed" name="test_problem007"/>
        <test duration="6" status="passed" name="test_problem008"/>
        <test duration="570" status="passed" name="test_problem009"/>
        <test duration="926" status="passed" name="test_problem010"/>
        <test duration="2" status="passed" name="test_problem011"/>
        <test duration="4330" status="passed" name="test_problem012"/>
        <test duration="0" status="passed" name="test_problem013"/>
        <test duration="5045" status="passed" name="test_problem014"/>
        <test duration="0" status="passed" name="test_problem015"/>
        <test duration="0" status="passed" name="test_problem016"/>
        <test duration="5" status="passed" name="test_problem017"/>
        <test duration="0" status="passed" name="test_problem018"/>
        <test duration="0" status="passed" name="test_problem019"/>
        <test duration="0" status="passed" name="test_problem020"/>
        <test duration="158" status="passed" name="test_problem021"/>
        <test duration="296" status="passed" name="test_problem022"/>
        <test duration="3674" status="passed" name="test_problem023"/>
        <test duration="1138" status="passed" name="test_problem024"/>
        <test duration="62" status="passed" name="test_problem025"/>
        <test duration="460" status="passed" name="test_problem026"/>
        <test duration="7686" status="passed" name="test_problem027"/>
        <test duration="0" status="passed" name="test_problem028"/>
        <test duration="22" status="passed" name="test_problem029"/>
        <test duration="5778" status="passed" name="test_problem030"/>
        <test duration="5573" status="passed" name="test_problem031"/>
        <test duration="766" status="passed" name="test_problem032"/>
        <test duration="52" status="passed" name="test_problem033"/>
        <test duration="62537" status="passed" name="test_problem034"/>
        <test duration="1223" status="passed" name="test_problem035"/>
        <test duration="383" status="passed" name="test_problem036"/>
        <test duration="1412" status="passed" name="test_problem037"/>
        <test duration="31" status="passed" name="test_problem038"/>
        <test duration="46510" status="passed" name="test_problem039"/>
        <test duration="191" status="passed" name="test_problem040"/>
        <test duration="2370" status="passed" name="test_problem041"/>
        <test duration="46" status="passed" name="test_problem042"/>
        <test duration="18608" status="passed" name="test_problem043"/>
        <test duration="2" status="failed" name="test_problem045">
            <output type="stderr">Failure
Traceback (most recent call last):
  File &amp;quot;/mnt/2F44B91B07695EE3/Programozas/python/PycharmProjects/ProjectEuler/regression_tests.py&amp;quot;, line 141, in test_problem045
    self.assertEquals(problem45(), 1533776805)
AssertionError: None != 1533776805
</output>
        </test>
        <test duration="80374" status="passed" name="test_problem047"/>
        <test duration="21" status="passed" name="test_problem048"/>
        <test duration="1360" status="passed" name="test_problem049"/>
        <test duration="1658" status="passed" name="test_problem050"/>
        <test duration="0" status="failed" name="test_problem056">
            <output type="stderr">Failure
Traceback (most recent call last):
  File &amp;quot;/mnt/2F44B91B07695EE3/Programozas/python/PycharmProjects/ProjectEuler/regression_tests.py&amp;quot;, line 156, in test_problem056
    self.assertEquals(problem56(), 972)
AssertionError: None != 972
</output>
        </test>
        <test duration="32" status="passed" name="test_problem067"/>
    </suite>
</testrun>
